data/input_orders.csv
ORDER_ID,SIDE,PRICE,QTY,TYPE
1,S,10100,100,N
2,B,10100,100,N
3,S,10100,100,N
4,S,10100,80,N
5,B,10100,150,N
6,B,9900,200,N
7,S,10100,50,N
8,B,9900,50,N
9,S,9900,50,N
10,B,10000,100,N
10,C,0,0,C
11,S,10000,100,N
12,S,10300,100,N
13,S,10300,80,N
14,S,10300,60,N
13,C,0,0,C
15,B,10300,200,N
